[2025-03-31T02:06:08.992+0000] {taskinstance.py:1103} INFO - Dependencies all met for dep_context=non-requeueable deps ti=<TaskInstance: covid_pipeline.validate_data manual__2025-03-31T02:06:04.031436+00:00 [queued]>
[2025-03-31T02:06:08.995+0000] {taskinstance.py:1103} INFO - Dependencies all met for dep_context=requeueable deps ti=<TaskInstance: covid_pipeline.validate_data manual__2025-03-31T02:06:04.031436+00:00 [queued]>
[2025-03-31T02:06:08.996+0000] {taskinstance.py:1308} INFO - Starting attempt 1 of 1
[2025-03-31T02:06:09.002+0000] {taskinstance.py:1327} INFO - Executing <Task(PythonOperator): validate_data> on 2025-03-31 02:06:04.031436+00:00
[2025-03-31T02:06:09.003+0000] {standard_task_runner.py:57} INFO - Started process 2625 to run task
[2025-03-31T02:06:09.005+0000] {standard_task_runner.py:84} INFO - Running: ['airflow', 'tasks', 'run', 'covid_pipeline', 'validate_data', 'manual__2025-03-31T02:06:04.031436+00:00', '--job-id', '19', '--raw', '--subdir', 'DAGS_FOLDER/covid_pipeline.py', '--cfg-path', '/tmp/tmp1655ewca']
[2025-03-31T02:06:09.005+0000] {standard_task_runner.py:85} INFO - Job 19: Subtask validate_data
[2025-03-31T02:06:09.018+0000] {task_command.py:410} INFO - Running <TaskInstance: covid_pipeline.validate_data manual__2025-03-31T02:06:04.031436+00:00 [running]> on host 246b607dca19
[2025-03-31T02:06:09.123+0000] {taskinstance.py:1547} INFO - Exporting env vars: AIRFLOW_CTX_DAG_OWNER='airflow' AIRFLOW_CTX_DAG_ID='covid_pipeline' AIRFLOW_CTX_TASK_ID='validate_data' AIRFLOW_CTX_EXECUTION_DATE='2025-03-31T02:06:04.031436+00:00' AIRFLOW_CTX_TRY_NUMBER='1' AIRFLOW_CTX_DAG_RUN_ID='manual__2025-03-31T02:06:04.031436+00:00'
[2025-03-31T02:06:09.998+0000] {warnings.py:110} WARNING - /home/airflow/.local/lib/python3.7/site-packages/snowflake/connector/options.py:109: UserWarning: You have an incompatible version of 'pyarrow' installed (11.0.0), please install a version that adheres to: 'pyarrow<10.1.0,>=10.0.1; extra == "pandas"'
  "pyarrow", installed_pyarrow_version, pandas_pyarrow_extra

[2025-03-31T02:06:10.853+0000] {logging_mixin.py:150} INFO - Columns: ['date', 'location_key', 'new_confirmed', 'new_deceased', 'new_recovered', 'new_tested', 'cumulative_confirmed', 'cumulative_deceased', 'cumulative_recovered', 'cumulative_tested']
[2025-03-31T02:06:10.855+0000] {taskinstance.py:1824} ERROR - Task failed with exception
Traceback (most recent call last):
  File "/home/airflow/.local/lib/python3.7/site-packages/airflow/operators/python.py", line 181, in execute
    return_value = self.execute_callable()
  File "/home/airflow/.local/lib/python3.7/site-packages/airflow/operators/python.py", line 198, in execute_callable
    return self.python_callable(*self.op_args, **self.op_kwargs)
  File "/opt/airflow/dags/covid_pipeline.py", line 22, in validate_data
    raise ValueError("'new_confirmed' has missing values!")
ValueError: 'new_confirmed' has missing values!
[2025-03-31T02:06:10.858+0000] {taskinstance.py:1350} INFO - Marking task as FAILED. dag_id=covid_pipeline, task_id=validate_data, execution_date=20250331T020604, start_date=20250331T020608, end_date=20250331T020610
[2025-03-31T02:06:10.864+0000] {standard_task_runner.py:109} ERROR - Failed to execute job 19 for task validate_data ('new_confirmed' has missing values!; 2625)
[2025-03-31T02:06:10.887+0000] {local_task_job_runner.py:225} INFO - Task exited with return code 1
[2025-03-31T02:06:10.910+0000] {taskinstance.py:2653} INFO - 0 downstream tasks scheduled from follow-on schedule check
