[2025-03-31T01:45:32.919+0000] {taskinstance.py:1103} INFO - Dependencies all met for dep_context=non-requeueable deps ti=<TaskInstance: covid_pipeline.download_data manual__2025-03-31T01:45:30.057614+00:00 [queued]>
[2025-03-31T01:45:32.922+0000] {taskinstance.py:1103} INFO - Dependencies all met for dep_context=requeueable deps ti=<TaskInstance: covid_pipeline.download_data manual__2025-03-31T01:45:30.057614+00:00 [queued]>
[2025-03-31T01:45:32.922+0000] {taskinstance.py:1308} INFO - Starting attempt 1 of 1
[2025-03-31T01:45:32.929+0000] {taskinstance.py:1327} INFO - Executing <Task(PythonOperator): download_data> on 2025-03-31 01:45:30.057614+00:00
[2025-03-31T01:45:32.931+0000] {standard_task_runner.py:57} INFO - Started process 2066 to run task
[2025-03-31T01:45:32.933+0000] {standard_task_runner.py:84} INFO - Running: ['airflow', 'tasks', 'run', 'covid_pipeline', 'download_data', 'manual__2025-03-31T01:45:30.057614+00:00', '--job-id', '9', '--raw', '--subdir', 'DAGS_FOLDER/covid_pipeline.py', '--cfg-path', '/tmp/tmpc4yh6oki']
[2025-03-31T01:45:32.934+0000] {standard_task_runner.py:85} INFO - Job 9: Subtask download_data
[2025-03-31T01:45:32.953+0000] {task_command.py:410} INFO - Running <TaskInstance: covid_pipeline.download_data manual__2025-03-31T01:45:30.057614+00:00 [running]> on host 246b607dca19
[2025-03-31T01:45:33.085+0000] {taskinstance.py:1547} INFO - Exporting env vars: AIRFLOW_CTX_DAG_OWNER='airflow' AIRFLOW_CTX_DAG_ID='covid_pipeline' AIRFLOW_CTX_TASK_ID='download_data' AIRFLOW_CTX_EXECUTION_DATE='2025-03-31T01:45:30.057614+00:00' AIRFLOW_CTX_TRY_NUMBER='1' AIRFLOW_CTX_DAG_RUN_ID='manual__2025-03-31T01:45:30.057614+00:00'
[2025-03-31T01:45:33.488+0000] {taskinstance.py:1824} ERROR - Task failed with exception
Traceback (most recent call last):
  File "/home/airflow/.local/lib/python3.7/site-packages/airflow/operators/python.py", line 181, in execute
    return_value = self.execute_callable()
  File "/home/airflow/.local/lib/python3.7/site-packages/airflow/operators/python.py", line 198, in execute_callable
    return self.python_callable(*self.op_args, **self.op_kwargs)
  File "/opt/airflow/dags/covid_pipeline.py", line 11, in download_covid_data
    df.to_csv("/Users/bharadwajvvs/Documents/Projects/DE-Mini-projects/airflow-orch/airflow-covid/data/covid_data.csv", index=False)  # Save to local folder
  File "/home/airflow/.local/lib/python3.7/site-packages/pandas/core/generic.py", line 3482, in to_csv
    storage_options=storage_options,
  File "/home/airflow/.local/lib/python3.7/site-packages/pandas/io/formats/format.py", line 1105, in to_csv
    csv_formatter.save()
  File "/home/airflow/.local/lib/python3.7/site-packages/pandas/io/formats/csvs.py", line 243, in save
    storage_options=self.storage_options,
  File "/home/airflow/.local/lib/python3.7/site-packages/pandas/io/common.py", line 707, in get_handle
    newline="",
FileNotFoundError: [Errno 2] No such file or directory: '/Users/bharadwajvvs/Documents/Projects/DE-Mini-projects/airflow-orch/airflow-covid/data/covid_data.csv'
[2025-03-31T01:45:33.496+0000] {taskinstance.py:1350} INFO - Marking task as FAILED. dag_id=covid_pipeline, task_id=download_data, execution_date=20250331T014530, start_date=20250331T014532, end_date=20250331T014533
[2025-03-31T01:45:33.504+0000] {standard_task_runner.py:109} ERROR - Failed to execute job 9 for task download_data ([Errno 2] No such file or directory: '/Users/bharadwajvvs/Documents/Projects/DE-Mini-projects/airflow-orch/airflow-covid/data/covid_data.csv'; 2066)
[2025-03-31T01:45:33.518+0000] {local_task_job_runner.py:225} INFO - Task exited with return code 1
[2025-03-31T01:45:33.529+0000] {taskinstance.py:2653} INFO - 0 downstream tasks scheduled from follow-on schedule check
