[2025-03-31T02:04:18.621+0000] {taskinstance.py:1103} INFO - Dependencies all met for dep_context=non-requeueable deps ti=<TaskInstance: covid_pipeline.download_data manual__2025-03-31T01:37:33.119723+00:00 [queued]>
[2025-03-31T02:04:18.627+0000] {taskinstance.py:1103} INFO - Dependencies all met for dep_context=requeueable deps ti=<TaskInstance: covid_pipeline.download_data manual__2025-03-31T01:37:33.119723+00:00 [queued]>
[2025-03-31T02:04:18.628+0000] {taskinstance.py:1308} INFO - Starting attempt 2 of 2
[2025-03-31T02:04:18.636+0000] {taskinstance.py:1327} INFO - Executing <Task(PythonOperator): download_data> on 2025-03-31 01:37:33.119723+00:00
[2025-03-31T02:04:18.641+0000] {standard_task_runner.py:57} INFO - Started process 2477 to run task
[2025-03-31T02:04:18.643+0000] {standard_task_runner.py:84} INFO - Running: ['airflow', 'tasks', 'run', 'covid_pipeline', 'download_data', 'manual__2025-03-31T01:37:33.119723+00:00', '--job-id', '15', '--raw', '--subdir', 'DAGS_FOLDER/covid_pipeline.py', '--cfg-path', '/tmp/tmp0kxikjn8']
[2025-03-31T02:04:18.645+0000] {standard_task_runner.py:85} INFO - Job 15: Subtask download_data
[2025-03-31T02:04:18.714+0000] {task_command.py:410} INFO - Running <TaskInstance: covid_pipeline.download_data manual__2025-03-31T01:37:33.119723+00:00 [running]> on host 246b607dca19
[2025-03-31T02:04:19.034+0000] {taskinstance.py:1824} ERROR - Task failed with exception
Traceback (most recent call last):
  File "/home/airflow/.local/lib/python3.7/site-packages/sqlalchemy/engine/base.py", line 1911, in _execute_context
    cursor, statement, parameters, context
  File "/home/airflow/.local/lib/python3.7/site-packages/sqlalchemy/engine/default.py", line 736, in do_execute
    cursor.execute(statement, parameters)
sqlite3.IntegrityError: FOREIGN KEY constraint failed

The above exception was the direct cause of the following exception:

Traceback (most recent call last):
  File "/home/airflow/.local/lib/python3.7/site-packages/airflow/models/taskinstance.py", line 1407, in _run_raw_task
    self._execute_task_with_callbacks(context, test_mode)
  File "/home/airflow/.local/lib/python3.7/site-packages/airflow/models/taskinstance.py", line 1534, in _execute_task_with_callbacks
    RenderedTaskInstanceFields.write(rtif)
  File "/home/airflow/.local/lib/python3.7/site-packages/airflow/utils/session.py", line 76, in wrapper
    return func(*args, session=session, **kwargs)
  File "/usr/local/lib/python3.7/contextlib.py", line 119, in __exit__
    next(self.gen)
  File "/home/airflow/.local/lib/python3.7/site-packages/airflow/utils/session.py", line 37, in create_session
    session.commit()
  File "/home/airflow/.local/lib/python3.7/site-packages/sqlalchemy/orm/session.py", line 1454, in commit
    self._transaction.commit(_to_root=self.future)
  File "/home/airflow/.local/lib/python3.7/site-packages/sqlalchemy/orm/session.py", line 832, in commit
    self._prepare_impl()
  File "/home/airflow/.local/lib/python3.7/site-packages/sqlalchemy/orm/session.py", line 811, in _prepare_impl
    self.session.flush()
  File "/home/airflow/.local/lib/python3.7/site-packages/sqlalchemy/orm/session.py", line 3449, in flush
    self._flush(objects)
  File "/home/airflow/.local/lib/python3.7/site-packages/sqlalchemy/orm/session.py", line 3589, in _flush
    transaction.rollback(_capture_exception=True)
  File "/home/airflow/.local/lib/python3.7/site-packages/sqlalchemy/util/langhelpers.py", line 72, in __exit__
    with_traceback=exc_tb,
  File "/home/airflow/.local/lib/python3.7/site-packages/sqlalchemy/util/compat.py", line 211, in raise_
    raise exception
  File "/home/airflow/.local/lib/python3.7/site-packages/sqlalchemy/orm/session.py", line 3549, in _flush
    flush_context.execute()
  File "/home/airflow/.local/lib/python3.7/site-packages/sqlalchemy/orm/unitofwork.py", line 456, in execute
    rec.execute(self)
  File "/home/airflow/.local/lib/python3.7/site-packages/sqlalchemy/orm/unitofwork.py", line 633, in execute
    uow,
  File "/home/airflow/.local/lib/python3.7/site-packages/sqlalchemy/orm/persistence.py", line 250, in save_obj
    insert,
  File "/home/airflow/.local/lib/python3.7/site-packages/sqlalchemy/orm/persistence.py", line 1098, in _emit_insert_statements
    statement, multiparams, execution_options=execution_options
  File "/home/airflow/.local/lib/python3.7/site-packages/sqlalchemy/engine/base.py", line 1710, in _execute_20
    return meth(self, args_10style, kwargs_10style, execution_options)
  File "/home/airflow/.local/lib/python3.7/site-packages/sqlalchemy/sql/elements.py", line 335, in _execute_on_connection
    self, multiparams, params, execution_options
  File "/home/airflow/.local/lib/python3.7/site-packages/sqlalchemy/engine/base.py", line 1587, in _execute_clauseelement
    cache_hit=cache_hit,
  File "/home/airflow/.local/lib/python3.7/site-packages/sqlalchemy/engine/base.py", line 1954, in _execute_context
    e, statement, parameters, cursor, context
  File "/home/airflow/.local/lib/python3.7/site-packages/sqlalchemy/engine/base.py", line 2135, in _handle_dbapi_exception
    sqlalchemy_exception, with_traceback=exc_info[2], from_=e
  File "/home/airflow/.local/lib/python3.7/site-packages/sqlalchemy/util/compat.py", line 211, in raise_
    raise exception
  File "/home/airflow/.local/lib/python3.7/site-packages/sqlalchemy/engine/base.py", line 1911, in _execute_context
    cursor, statement, parameters, context
  File "/home/airflow/.local/lib/python3.7/site-packages/sqlalchemy/engine/default.py", line 736, in do_execute
    cursor.execute(statement, parameters)
sqlalchemy.exc.IntegrityError: (sqlite3.IntegrityError) FOREIGN KEY constraint failed
[SQL: INSERT INTO rendered_task_instance_fields (dag_id, task_id, run_id, map_index, rendered_fields, k8s_pod_yaml) VALUES (?, ?, ?, ?, ?, ?)]
[parameters: ('covid_pipeline', 'download_data', 'manual__2025-03-31T01:37:33.119723+00:00', -1, '{"templates_dict": null, "op_args": [], "op_kwargs": {}}', 'null')]
(Background on this error at: https://sqlalche.me/e/14/gkpj)
[2025-03-31T02:04:19.054+0000] {taskinstance.py:1350} INFO - Marking task as FAILED. dag_id=covid_pipeline, task_id=download_data, execution_date=20250331T013733, start_date=20250331T020418, end_date=20250331T020419
[2025-03-31T02:04:19.085+0000] {standard_task_runner.py:109} ERROR - Failed to execute job 15 for task download_data ((sqlite3.IntegrityError) FOREIGN KEY constraint failed
[SQL: INSERT INTO task_fail (task_id, dag_id, run_id, map_index, start_date, end_date, duration) VALUES (?, ?, ?, ?, ?, ?, ?)]
[parameters: ('download_data', 'covid_pipeline', 'manual__2025-03-31T01:37:33.119723+00:00', -1, '2025-03-31 02:04:18.622067', '2025-03-31 02:04:19.053955', 0)]
(Background on this error at: https://sqlalche.me/e/14/gkpj); 2477)
[2025-03-31T02:04:19.115+0000] {local_task_job_runner.py:225} INFO - Task exited with return code 1
[2025-03-31T02:04:19.148+0000] {taskinstance.py:2653} INFO - 0 downstream tasks scheduled from follow-on schedule check
