[2025-03-31T01:49:09.166+0000] {taskinstance.py:1103} INFO - Dependencies all met for dep_context=non-requeueable deps ti=<TaskInstance: covid_pipeline.validate_data manual__2025-03-31T01:49:04.275317+00:00 [queued]>
[2025-03-31T01:49:09.169+0000] {taskinstance.py:1103} INFO - Dependencies all met for dep_context=requeueable deps ti=<TaskInstance: covid_pipeline.validate_data manual__2025-03-31T01:49:04.275317+00:00 [queued]>
[2025-03-31T01:49:09.169+0000] {taskinstance.py:1308} INFO - Starting attempt 1 of 1
[2025-03-31T01:49:09.177+0000] {taskinstance.py:1327} INFO - Executing <Task(PythonOperator): validate_data> on 2025-03-31 01:49:04.275317+00:00
[2025-03-31T01:49:09.178+0000] {standard_task_runner.py:57} INFO - Started process 2171 to run task
[2025-03-31T01:49:09.180+0000] {standard_task_runner.py:84} INFO - Running: ['airflow', 'tasks', 'run', 'covid_pipeline', 'validate_data', 'manual__2025-03-31T01:49:04.275317+00:00', '--job-id', '11', '--raw', '--subdir', 'DAGS_FOLDER/covid_pipeline.py', '--cfg-path', '/tmp/tmpgdicpvfr']
[2025-03-31T01:49:09.181+0000] {standard_task_runner.py:85} INFO - Job 11: Subtask validate_data
[2025-03-31T01:49:09.195+0000] {task_command.py:410} INFO - Running <TaskInstance: covid_pipeline.validate_data manual__2025-03-31T01:49:04.275317+00:00 [running]> on host 246b607dca19
[2025-03-31T01:49:09.292+0000] {taskinstance.py:1547} INFO - Exporting env vars: AIRFLOW_CTX_DAG_OWNER='airflow' AIRFLOW_CTX_DAG_ID='covid_pipeline' AIRFLOW_CTX_TASK_ID='validate_data' AIRFLOW_CTX_EXECUTION_DATE='2025-03-31T01:49:04.275317+00:00' AIRFLOW_CTX_TRY_NUMBER='1' AIRFLOW_CTX_DAG_RUN_ID='manual__2025-03-31T01:49:04.275317+00:00'
[2025-03-31T01:49:10.714+0000] {warnings.py:110} WARNING - /home/airflow/.local/lib/python3.7/site-packages/snowflake/connector/options.py:109: UserWarning: You have an incompatible version of 'pyarrow' installed (11.0.0), please install a version that adheres to: 'pyarrow<10.1.0,>=10.0.1; extra == "pandas"'
  "pyarrow", installed_pyarrow_version, pandas_pyarrow_extra

[2025-03-31T01:49:11.585+0000] {taskinstance.py:1824} ERROR - Task failed with exception
Traceback (most recent call last):
  File "/home/airflow/.local/lib/python3.7/site-packages/pandas/core/indexes/base.py", line 3361, in get_loc
    return self._engine.get_loc(casted_key)
  File "pandas/_libs/index.pyx", line 76, in pandas._libs.index.IndexEngine.get_loc
  File "pandas/_libs/index.pyx", line 108, in pandas._libs.index.IndexEngine.get_loc
  File "pandas/_libs/hashtable_class_helper.pxi", line 5198, in pandas._libs.hashtable.PyObjectHashTable.get_item
  File "pandas/_libs/hashtable_class_helper.pxi", line 5206, in pandas._libs.hashtable.PyObjectHashTable.get_item
KeyError: 'Confirmed'

The above exception was the direct cause of the following exception:

Traceback (most recent call last):
  File "/home/airflow/.local/lib/python3.7/site-packages/airflow/operators/python.py", line 181, in execute
    return_value = self.execute_callable()
  File "/home/airflow/.local/lib/python3.7/site-packages/airflow/operators/python.py", line 198, in execute_callable
    return self.python_callable(*self.op_args, **self.op_kwargs)
  File "/opt/airflow/dags/covid_pipeline.py", line 20, in validate_data
    result = df.expect_column_values_to_not_be_null("Confirmed")
  File "/home/airflow/.local/lib/python3.7/site-packages/great_expectations/data_asset/util.py", line 76, in f
    return self.mthd(obj, *args, **kwargs)
  File "/home/airflow/.local/lib/python3.7/site-packages/great_expectations/data_asset/data_asset.py", line 288, in wrapper
    raise err
  File "/home/airflow/.local/lib/python3.7/site-packages/great_expectations/data_asset/data_asset.py", line 275, in wrapper
    return_obj = func(self, **evaluation_args)
  File "/home/airflow/.local/lib/python3.7/site-packages/great_expectations/dataset/pandas_dataset.py", line 81, in inner_wrapper
    series = data[column]
  File "/home/airflow/.local/lib/python3.7/site-packages/pandas/core/frame.py", line 3458, in __getitem__
    indexer = self.columns.get_loc(key)
  File "/home/airflow/.local/lib/python3.7/site-packages/pandas/core/indexes/base.py", line 3363, in get_loc
    raise KeyError(key) from err
KeyError: 'Confirmed'
[2025-03-31T01:49:11.599+0000] {taskinstance.py:1350} INFO - Marking task as FAILED. dag_id=covid_pipeline, task_id=validate_data, execution_date=20250331T014904, start_date=20250331T014909, end_date=20250331T014911
[2025-03-31T01:49:11.608+0000] {standard_task_runner.py:109} ERROR - Failed to execute job 11 for task validate_data ('Confirmed'; 2171)
[2025-03-31T01:49:11.628+0000] {local_task_job_runner.py:225} INFO - Task exited with return code 1
[2025-03-31T01:49:11.648+0000] {taskinstance.py:2653} INFO - 0 downstream tasks scheduled from follow-on schedule check
