[2025-03-31T01:35:00.736+0000] {taskinstance.py:1103} INFO - Dependencies all met for dep_context=non-requeueable deps ti=<TaskInstance: covid_pipeline.download_data scheduled__2025-03-30T00:00:00+00:00 [queued]>
[2025-03-31T01:35:00.739+0000] {taskinstance.py:1103} INFO - Dependencies all met for dep_context=requeueable deps ti=<TaskInstance: covid_pipeline.download_data scheduled__2025-03-30T00:00:00+00:00 [queued]>
[2025-03-31T01:35:00.739+0000] {taskinstance.py:1308} INFO - Starting attempt 1 of 1
[2025-03-31T01:35:00.751+0000] {taskinstance.py:1327} INFO - Executing <Task(PythonOperator): download_data> on 2025-03-30 00:00:00+00:00
[2025-03-31T01:35:00.761+0000] {standard_task_runner.py:57} INFO - Started process 1796 to run task
[2025-03-31T01:35:00.766+0000] {standard_task_runner.py:84} INFO - Running: ['airflow', 'tasks', 'run', 'covid_pipeline', 'download_data', 'scheduled__2025-03-30T00:00:00+00:00', '--job-id', '3', '--raw', '--subdir', 'DAGS_FOLDER/covid_pipeline.py', '--cfg-path', '/tmp/tmp894gbhys']
[2025-03-31T01:35:00.767+0000] {standard_task_runner.py:85} INFO - Job 3: Subtask download_data
[2025-03-31T01:35:00.792+0000] {task_command.py:410} INFO - Running <TaskInstance: covid_pipeline.download_data scheduled__2025-03-30T00:00:00+00:00 [running]> on host 246b607dca19
[2025-03-31T01:35:00.954+0000] {taskinstance.py:1547} INFO - Exporting env vars: AIRFLOW_CTX_DAG_OWNER='airflow' AIRFLOW_CTX_DAG_ID='covid_pipeline' AIRFLOW_CTX_TASK_ID='download_data' AIRFLOW_CTX_EXECUTION_DATE='2025-03-30T00:00:00+00:00' AIRFLOW_CTX_TRY_NUMBER='1' AIRFLOW_CTX_DAG_RUN_ID='scheduled__2025-03-30T00:00:00+00:00'
[2025-03-31T01:35:01.166+0000] {taskinstance.py:1824} ERROR - Task failed with exception
Traceback (most recent call last):
  File "/home/airflow/.local/lib/python3.7/site-packages/airflow/operators/python.py", line 181, in execute
    return_value = self.execute_callable()
  File "/home/airflow/.local/lib/python3.7/site-packages/airflow/operators/python.py", line 198, in execute_callable
    return self.python_callable(*self.op_args, **self.op_kwargs)
  File "/opt/airflow/dags/covid_pipeline.py", line 10, in download_covid_data
    df = pd.read_csv(url)
  File "/home/airflow/.local/lib/python3.7/site-packages/pandas/util/_decorators.py", line 311, in wrapper
    return func(*args, **kwargs)
  File "/home/airflow/.local/lib/python3.7/site-packages/pandas/io/parsers/readers.py", line 586, in read_csv
    return _read(filepath_or_buffer, kwds)
  File "/home/airflow/.local/lib/python3.7/site-packages/pandas/io/parsers/readers.py", line 482, in _read
    parser = TextFileReader(filepath_or_buffer, **kwds)
  File "/home/airflow/.local/lib/python3.7/site-packages/pandas/io/parsers/readers.py", line 811, in __init__
    self._engine = self._make_engine(self.engine)
  File "/home/airflow/.local/lib/python3.7/site-packages/pandas/io/parsers/readers.py", line 1040, in _make_engine
    return mapping[engine](self.f, **self.options)  # type: ignore[call-arg]
  File "/home/airflow/.local/lib/python3.7/site-packages/pandas/io/parsers/c_parser_wrapper.py", line 51, in __init__
    self._open_handles(src, kwds)
  File "/home/airflow/.local/lib/python3.7/site-packages/pandas/io/parsers/base_parser.py", line 229, in _open_handles
    errors=kwds.get("encoding_errors", "strict"),
  File "/home/airflow/.local/lib/python3.7/site-packages/pandas/io/common.py", line 614, in get_handle
    storage_options=storage_options,
  File "/home/airflow/.local/lib/python3.7/site-packages/pandas/io/common.py", line 312, in _get_filepath_or_buffer
    with urlopen(req_info) as req:
  File "/home/airflow/.local/lib/python3.7/site-packages/pandas/io/common.py", line 212, in urlopen
    return urllib.request.urlopen(*args, **kwargs)
  File "/usr/local/lib/python3.7/urllib/request.py", line 222, in urlopen
    return opener.open(url, data, timeout)
  File "/usr/local/lib/python3.7/urllib/request.py", line 531, in open
    response = meth(req, response)
  File "/usr/local/lib/python3.7/urllib/request.py", line 641, in http_response
    'http', request, response, code, msg, hdrs)
  File "/usr/local/lib/python3.7/urllib/request.py", line 569, in error
    return self._call_chain(*args)
  File "/usr/local/lib/python3.7/urllib/request.py", line 503, in _call_chain
    result = func(*args)
  File "/usr/local/lib/python3.7/urllib/request.py", line 649, in http_error_default
    raise HTTPError(req.full_url, code, msg, hdrs, fp)
urllib.error.HTTPError: HTTP Error 404: Not Found
[2025-03-31T01:35:01.184+0000] {taskinstance.py:1350} INFO - Marking task as FAILED. dag_id=covid_pipeline, task_id=download_data, execution_date=20250330T000000, start_date=20250331T013500, end_date=20250331T013501
[2025-03-31T01:35:01.194+0000] {standard_task_runner.py:109} ERROR - Failed to execute job 3 for task download_data (HTTP Error 404: Not Found; 1796)
[2025-03-31T01:35:01.243+0000] {local_task_job_runner.py:225} INFO - Task exited with return code 1
[2025-03-31T01:35:01.255+0000] {taskinstance.py:2653} INFO - 0 downstream tasks scheduled from follow-on schedule check
